Workbook

Sheet Rotations
A1: Option 1 | I1: Option 2 | Q1: Option 3 | Y1: Option 4 | AG1: Option 5 | AO1: Option 6
A2: 32 | B2: 16 | C2: 8 | D2: 4 | E2: 2 | F2: 1 | G2: Value | H2: Char | I2: 32 | J2: 16 | K2: 8 | L2: 4 | M2: 2 | N2: 1 | O2: Value | P2: Char | Q2: 32 | R2: 16 | S2: 8 | T2: 4 | U2: 2 | V2: 1 | W2: Value | X2: Char | Y2: 32 | Z2: 16 | AA2: 8 | AB2: 4 | AC2: 2 | AD2: 1 | AE2: Value | AF2: Char | AG2: 32 | AH2: 16 | AI2: 8 | AJ2: 4 | AK2: 2 | AL2: 1 | AM2: Value | AN2: Char | AO2: 32 | AP2: 16 | AQ2: 8 | AR2: 4 | AS2: 2 | AT2: 1 | AU2: Value | AV2: Char
A3: 0 | B3: 0 | C3: 0 | D3: 0 | E3: 0 | F3: 1 | G3: =F3+E3*2^1+D3*2^2+C3*2^3+B3*2^4+A3*2^5 -> 1 | H3: =INDEX('Character Map'!A2:A65,G3,1) -> A | I3: 0 | J3: 0 | K3: 0 | L3: 0 | M3: 1 | N3: 0 | O3: =N3+M3*2^1+L3*2^2+K3*2^3+J3*2^4+I3*2^5 -> 2 | P3: =INDEX('Character Map'!A2:A65,O3,1) -> B | Q3: 0 | R3: 0 | S3: 0 | T3: 1 | U3: 0 | V3: 0 | W3: =V3+U3*2^1+T3*2^2+S3*2^3+R3*2^4+Q3*2^5 -> 4 | X3: =INDEX('Character Map'!A2:A65,W3,1) -> D | Y3: 0 | Z3: 0 | AA3: 1 | AB3: 0 | AC3: 0 | AD3: 0 | AE3: =AD3+AC3*2^1+AB3*2^2+AA3*2^3+Z3*2^4+Y3*2^5 -> 8 | AF3: =INDEX('Character Map'!A2:A65,AE3,1) -> H | AG3: 0 | AH3: 1 | AI3: 0 | AJ3: 0 | AK3: 0 | AL3: 0 | AM3: =AL3+AK3*2^1+AJ3*2^2+AI3*2^3+AH3*2^4+AG3*2^5 -> 16 | AN3: =INDEX('Character Map'!A2:A65,AM3,1) -> P | AO3: 1 | AP3: 0 | AQ3: 0 | AR3: 0 | AS3: 0 | AT3: 0 | AU3: =AT3+AS3*2^1+AR3*2^2+AQ3*2^3+AP3*2^4+AO3*2^5 -> 32 | AV3: =INDEX('Character Map'!A2:A65,AU3,1) -> 5
A4: 0 | B4: 0 | C4: 0 | D4: 0 | E4: 1 | F4: 0 | G4: =F4+E4*2^1+D4*2^2+C4*2^3+B4*2^4+A4*2^5 -> 2 | H4: =INDEX('Character Map'!A2:A65,G4,1) -> B | I4: 0 | J4: 0 | K4: 0 | L4: 1 | M4: 0 | N4: 0 | O4: =N4+M4*2^1+L4*2^2+K4*2^3+J4*2^4+I4*2^5 -> 4 | P4: =INDEX('Character Map'!A2:A65,O4,1) -> D | Q4: 0 | R4: 0 | S4: 1 | T4: 0 | U4: 0 | V4: 0 | W4: =V4+U4*2^1+T4*2^2+S4*2^3+R4*2^4+Q4*2^5 -> 8 | X4: =INDEX('Character Map'!A2:A65,W4,1) -> H | Y4: 0 | Z4: 1 | AA4: 0 | AB4: 0 | AC4: 0 | AD4: 0 | AE4: =AD4+AC4*2^1+AB4*2^2+AA4*2^3+Z4*2^4+Y4*2^5 -> 16 | AF4: =INDEX('Character Map'!A2:A65,AE4,1) -> P | AG4: 1 | AH4: 0 | AI4: 0 | AJ4: 0 | AK4: 0 | AL4: 0 | AM4: =AL4+AK4*2^1+AJ4*2^2+AI4*2^3+AH4*2^4+AG4*2^5 -> 32 | AN4: =INDEX('Character Map'!A2:A65,AM4,1) -> 5 | AO4: 0 | AP4: 0 | AQ4: 0 | AR4: 0 | AS4: 0 | AT4: 1 | AU4: =AT4+AS4*2^1+AR4*2^2+AQ4*2^3+AP4*2^4+AO4*2^5 -> 1 | AV4: =INDEX('Character Map'!A2:A65,AU4,1) -> A
A5: 0 | B5: 0 | C5: 0 | D5: 0 | E5: 1 | F5: 1 | G5: =F5+E5*2^1+D5*2^2+C5*2^3+B5*2^4+A5*2^5 -> 3 | H5: =INDEX('Character Map'!A2:A65,G5,1) -> C | I5: 0 | J5: 0 | K5: 0 | L5: 1 | M5: 1 | N5: 0 | O5: =N5+M5*2^1+L5*2^2+K5*2^3+J5*2^4+I5*2^5 -> 6 | P5: =INDEX('Character Map'!A2:A65,O5,1) -> F | Q5: 0 | R5: 0 | S5: 1 | T5: 1 | U5: 0 | V5: 0 | W5: =V5+U5*2^1+T5*2^2+S5*2^3+R5*2^4+Q5*2^5 -> 12 | X5: =INDEX('Character Map'!A2:A65,W5,1) -> L | Y5: 0 | Z5: 1 | AA5: 1 | AB5: 0 | AC5: 0 | AD5: 0 | AE5: =AD5+AC5*2^1+AB5*2^2+AA5*2^3+Z5*2^4+Y5*2^5 -> 24 | AF5: =INDEX('Character Map'!A2:A65,AE5,1) -> X | AG5: 1 | AH5: 1 | AI5: 0 | AJ5: 0 | AK5: 0 | AL5: 0 | AM5: =AL5+AK5*2^1+AJ5*2^2+AI5*2^3+AH5*2^4+AG5*2^5 -> 48 | AN5: =INDEX('Character Map'!A2:A65,AM5,1) -> # | AO5: 1 | AP5: 0 | AQ5: 0 | AR5: 0 | AS5: 0 | AT5: 1 | AU5: =AT5+AS5*2^1+AR5*2^2+AQ5*2^3+AP5*2^4+AO5*2^5 -> 33 | AV5: =INDEX('Character Map'!A2:A65,AU5,1) -> 6
A6: 0 | B6: 0 | C6: 0 | D6: 1 | E6: 0 | F6: 0 | G6: =F6+E6*2^1+D6*2^2+C6*2^3+B6*2^4+A6*2^5 -> 4 | H6: =INDEX('Character Map'!A2:A65,G6,1) -> D | I6: 0 | J6: 0 | K6: 1 | L6: 0 | M6: 0 | N6: 0 | O6: =N6+M6*2^1+L6*2^2+K6*2^3+J6*2^4+I6*2^5 -> 8 | P6: =INDEX('Character Map'!A2:A65,O6,1) -> H | Q6: 0 | R6: 1 | S6: 0 | T6: 0 | U6: 0 | V6: 0 | W6: =V6+U6*2^1+T6*2^2+S6*2^3+R6*2^4+Q6*2^5 -> 16 | X6: =INDEX('Character Map'!A2:A65,W6,1) -> P | Y6: 1 | Z6: 0 | AA6: 0 | AB6: 0 | AC6: 0 | AD6: 0 | AE6: =AD6+AC6*2^1+AB6*2^2+AA6*2^3+Z6*2^4+Y6*2^5 -> 32 | AF6: =INDEX('Character Map'!A2:A65,AE6,1) -> 5 | AG6: 0 | AH6: 0 | AI6: 0 | AJ6: 0 | AK6: 0 | AL6: 1 | AM6: =AL6+AK6*2^1+AJ6*2^2+AI6*2^3+AH6*2^4+AG6*2^5 -> 1 | AN6: =INDEX('Character Map'!A2:A65,AM6,1) -> A | AO6: 0 | AP6: 0 | AQ6: 0 | AR6: 0 | AS6: 1 | AT6: 0 | AU6: =AT6+AS6*2^1+AR6*2^2+AQ6*2^3+AP6*2^4+AO6*2^5 -> 2 | AV6: =INDEX('Character Map'!A2:A65,AU6,1) -> B
A7: 0 | B7: 0 | C7: 0 | D7: 1 | E7: 0 | F7: 1 | G7: =F7+E7*2^1+D7*2^2+C7*2^3+B7*2^4+A7*2^5 -> 5 | H7: =INDEX('Character Map'!A2:A65,G7,1) -> E | I7: 0 | J7: 0 | K7: 1 | L7: 0 | M7: 1 | N7: 0 | O7: =N7+M7*2^1+L7*2^2+K7*2^3+J7*2^4+I7*2^5 -> 10 | P7: =INDEX('Character Map'!A2:A65,O7,1) -> J | Q7: 0 | R7: 1 | S7: 0 | T7: 1 | U7: 0 | V7: 0 | W7: =V7+U7*2^1+T7*2^2+S7*2^3+R7*2^4+Q7*2^5 -> 20 | X7: =INDEX('Character Map'!A2:A65,W7,1) -> T | Y7: 1 | Z7: 0 | AA7: 1 | AB7: 0 | AC7: 0 | AD7: 0 | AE7: =AD7+AC7*2^1+AB7*2^2+AA7*2^3+Z7*2^4+Y7*2^5 -> 40 | AF7: =INDEX('Character Map'!A2:A65,AE7,1) -> 4 | AG7: 0 | AH7: 1 | AI7: 0 | AJ7: 0 | AK7: 0 | AL7: 1 | AM7: =AL7+AK7*2^1+AJ7*2^2+AI7*2^3+AH7*2^4+AG7*2^5 -> 17 | AN7: =INDEX('Character Map'!A2:A65,AM7,1) -> Q | AO7: 1 | AP7: 0 | AQ7: 0 | AR7: 0 | AS7: 1 | AT7: 0 | AU7: =AT7+AS7*2^1+AR7*2^2+AQ7*2^3+AP7*2^4+AO7*2^5 -> 34 | AV7: =INDEX('Character Map'!A2:A65,AU7,1) -> 7
A8: 0 | B8: 0 | C8: 0 | D8: 1 | E8: 1 | F8: 0 | G8: =F8+E8*2^1+D8*2^2+C8*2^3+B8*2^4+A8*2^5 -> 6 | H8: =INDEX('Character Map'!A2:A65,G8,1) -> F | I8: 0 | J8: 0 | K8: 1 | L8: 1 | M8: 0 | N8: 0 | O8: =N8+M8*2^1+L8*2^2+K8*2^3+J8*2^4+I8*2^5 -> 12 | P8: =INDEX('Character Map'!A2:A65,O8,1) -> L | Q8: 0 | R8: 1 | S8: 1 | T8: 0 | U8: 0 | V8: 0 | W8: =V8+U8*2^1+T8*2^2+S8*2^3+R8*2^4+Q8*2^5 -> 24 | X8: =INDEX('Character Map'!A2:A65,W8,1) -> X | Y8: 1 | Z8: 1 | AA8: 0 | AB8: 0 | AC8: 0 | AD8: 0 | AE8: =AD8+AC8*2^1+AB8*2^2+AA8*2^3+Z8*2^4+Y8*2^5 -> 48 | AF8: =INDEX('Character Map'!A2:A65,AE8,1) -> # | AG8: 1 | AH8: 0 | AI8: 0 | AJ8: 0 | AK8: 0 | AL8: 1 | AM8: =AL8+AK8*2^1+AJ8*2^2+AI8*2^3+AH8*2^4+AG8*2^5 -> 33 | AN8: =INDEX('Character Map'!A2:A65,AM8,1) -> 6 | AO8: 0 | AP8: 0 | AQ8: 0 | AR8: 0 | AS8: 1 | AT8: 1 | AU8: =AT8+AS8*2^1+AR8*2^2+AQ8*2^3+AP8*2^4+AO8*2^5 -> 3 | AV8: =INDEX('Character Map'!A2:A65,AU8,1) -> C
A9: 0 | B9: 0 | C9: 0 | D9: 1 | E9: 1 | F9: 1 | G9: =F9+E9*2^1+D9*2^2+C9*2^3+B9*2^4+A9*2^5 -> 7 | H9: =INDEX('Character Map'!A2:A65,G9,1) -> G | I9: 0 | J9: 0 | K9: 1 | L9: 1 | M9: 1 | N9: 0 | O9: =N9+M9*2^1+L9*2^2+K9*2^3+J9*2^4+I9*2^5 -> 14 | P9: =INDEX('Character Map'!A2:A65,O9,1) -> N | Q9: 0 | R9: 1 | S9: 1 | T9: 1 | U9: 0 | V9: 0 | W9: =V9+U9*2^1+T9*2^2+S9*2^3+R9*2^4+Q9*2^5 -> 28 | X9: =INDEX('Character Map'!A2:A65,W9,1) -> 1 | Y9: 1 | Z9: 1 | AA9: 1 | AB9: 0 | AC9: 0 | AD9: 0 | AE9: =AD9+AC9*2^1+AB9*2^2+AA9*2^3+Z9*2^4+Y9*2^5 -> 56 | AF9: =INDEX('Character Map'!A2:A65,AE9,1) -> O | AG9: 1 | AH9: 1 | AI9: 0 | AJ9: 0 | AK9: 0 | AL9: 1 | AM9: =AL9+AK9*2^1+AJ9*2^2+AI9*2^3+AH9*2^4+AG9*2^5 -> 49 | AN9: =INDEX('Character Map'!A2:A65,AM9,1) -> 3 | AO9: 1 | AP9: 0 | AQ9: 0 | AR9: 0 | AS9: 1 | AT9: 1 | AU9: =AT9+AS9*2^1+AR9*2^2+AQ9*2^3+AP9*2^4+AO9*2^5 -> 35 | AV9: =INDEX('Character Map'!A2:A65,AU9,1) -> 8
A10: 0 | B10: 0 | C10: 1 | D10: 0 | E10: 0 | F10: 0 | G10: =F10+E10*2^1+D10*2^2+C10*2^3+B10*2^4+A10*2^5 -> 8 | H10: =INDEX('Character Map'!A2:A65,G10,1) -> H | I10: 0 | J10: 1 | K10: 0 | L10: 0 | M10: 0 | N10: 0 | O10: =N10+M10*2^1+L10*2^2+K10*2^3+J10*2^4+I10*2^5 -> 16 | P10: =INDEX('Character Map'!A2:A65,O10,1) -> P | Q10: 1 | R10: 0 | S10: 0 | T10: 0 | U10: 0 | V10: 0 | W10: =V10+U10*2^1+T10*2^2+S10*2^3+R10*2^4+Q10*2^5 -> 32 | X10: =INDEX('Character Map'!A2:A65,W10,1) -> 5 | Y10: 0 | Z10: 0 | AA10: 0 | AB10: 0 | AC10: 0 | AD10: 1 | AE10: =AD10+AC10*2^1+AB10*2^2+AA10*2^3+Z10*2^4+Y10*2^5 -> 1 | AF10: =INDEX('Character Map'!A2:A65,AE10,1) -> A | AG10: 0 | AH10: 0 | AI10: 0 | AJ10: 0 | AK10: 1 | AL10: 0 | AM10: =AL10+AK10*2^1+AJ10*2^2+AI10*2^3+AH10*2^4+AG10*2^5 -> 2 | AN10: =INDEX('Character Map'!A2:A65,AM10,1) -> B | AO10: 0 | AP10: 0 | AQ10: 0 | AR10: 1 | AS10: 0 | AT10: 0 | AU10: =AT10+AS10*2^1+AR10*2^2+AQ10*2^3+AP10*2^4+AO10*2^5 -> 4 | AV10: =INDEX('Character Map'!A2:A65,AU10,1) -> D
A11: 0 | B11: 0 | C11: 1 | D11: 0 | E11: 0 | F11: 1 | G11: =F11+E11*2^1+D11*2^2+C11*2^3+B11*2^4+A11*2^5 -> 9 | H11: =INDEX('Character Map'!A2:A65,G11,1) -> I | I11: 0 | J11: 1 | K11: 0 | L11: 0 | M11: 1 | N11: 0 | O11: =N11+M11*2^1+L11*2^2+K11*2^3+J11*2^4+I11*2^5 -> 18 | P11: =INDEX('Character Map'!A2:A65,O11,1) -> R | Q11: 1 | R11: 0 | S11: 0 | T11: 1 | U11: 0 | V11: 0 | W11: =V11+U11*2^1+T11*2^2+S11*2^3+R11*2^4+Q11*2^5 -> 36 | X11: =INDEX('Character Map'!A2:A65,W11,1) -> 9 | Y11: 0 | Z11: 0 | AA11: 1 | AB11: 0 | AC11: 0 | AD11: 1 | AE11: =AD11+AC11*2^1+AB11*2^2+AA11*2^3+Z11*2^4+Y11*2^5 -> 9 | AF11: =INDEX('Character Map'!A2:A65,AE11,1) -> I | AG11: 0 | AH11: 1 | AI11: 0 | AJ11: 0 | AK11: 1 | AL11: 0 | AM11: =AL11+AK11*2^1+AJ11*2^2+AI11*2^3+AH11*2^4+AG11*2^5 -> 18 | AN11: =INDEX('Character Map'!A2:A65,AM11,1) -> R | AO11: 1 | AP11: 0 | AQ11: 0 | AR11: 1 | AS11: 0 | AT11: 0 | AU11: =AT11+AS11*2^1+AR11*2^2+AQ11*2^3+AP11*2^4+AO11*2^5 -> 36 | AV11: =INDEX('Character Map'!A2:A65,AU11,1) -> 9
A12: 0 | B12: 0 | C12: 1 | D12: 0 | E12: 1 | F12: 0 | G12: =F12+E12*2^1+D12*2^2+C12*2^3+B12*2^4+A12*2^5 -> 10 | H12: =INDEX('Character Map'!A2:A65,G12,1) -> J | I12: 0 | J12: 1 | K12: 0 | L12: 1 | M12: 0 | N12: 0 | O12: =N12+M12*2^1+L12*2^2+K12*2^3+J12*2^4+I12*2^5 -> 20 | P12: =INDEX('Character Map'!A2:A65,O12,1) -> T | Q12: 1 | R12: 0 | S12: 1 | T12: 0 | U12: 0 | V12: 0 | W12: =V12+U12*2^1+T12*2^2+S12*2^3+R12*2^4+Q12*2^5 -> 40 | X12: =INDEX('Character Map'!A2:A65,W12,1) -> 4 | Y12: 0 | Z12: 1 | AA12: 0 | AB12: 0 | AC12: 0 | AD12: 1 | AE12: =AD12+AC12*2^1+AB12*2^2+AA12*2^3+Z12*2^4+Y12*2^5 -> 17 | AF12: =INDEX('Character Map'!A2:A65,AE12,1) -> Q | AG12: 1 | AH12: 0 | AI12: 0 | AJ12: 0 | AK12: 1 | AL12: 0 | AM12: =AL12+AK12*2^1+AJ12*2^2+AI12*2^3+AH12*2^4+AG12*2^5 -> 34 | AN12: =INDEX('Character Map'!A2:A65,AM12,1) -> 7 | AO12: 0 | AP12: 0 | AQ12: 0 | AR12: 1 | AS12: 0 | AT12: 1 | AU12: =AT12+AS12*2^1+AR12*2^2+AQ12*2^3+AP12*2^4+AO12*2^5 -> 5 | AV12: =INDEX('Character Map'!A2:A65,AU12,1) -> E
A13: 0 | B13: 0 | C13: 1 | D13: 0 | E13: 1 | F13: 1 | G13: =F13+E13*2^1+D13*2^2+C13*2^3+B13*2^4+A13*2^5 -> 11 | H13: =INDEX('Character Map'!A2:A65,G13,1) -> K | I13: 0 | J13: 1 | K13: 0 | L13: 1 | M13: 1 | N13: 0 | O13: =N13+M13*2^1+L13*2^2+K13*2^3+J13*2^4+I13*2^5 -> 22 | P13: =INDEX('Character Map'!A2:A65,O13,1) -> V | Q13: 1 | R13: 0 | S13: 1 | T13: 1 | U13: 0 | V13: 0 | W13: =V13+U13*2^1+T13*2^2+S13*2^3+R13*2^4+Q13*2^5 -> 44 | X13: =INDEX('Character Map'!A2:A65,W13,1) -> S | Y13: 0 | Z13: 1 | AA13: 1 | AB13: 0 | AC13: 0 | AD13: 1 | AE13: =AD13+AC13*2^1+AB13*2^2+AA13*2^3+Z13*2^4+Y13*2^5 -> 25 | AF13: =INDEX('Character Map'!A2:A65,AE13,1) -> Y | AG13: 1 | AH13: 1 | AI13: 0 | AJ13: 0 | AK13: 1 | AL13: 0 | AM13: =AL13+AK13*2^1+AJ13*2^2+AI13*2^3+AH13*2^4+AG13*2^5 -> 50 | AN13: =INDEX('Character Map'!A2:A65,AM13,1) -> M | AO13: 1 | AP13: 0 | AQ13: 0 | AR13: 1 | AS13: 0 | AT13: 1 | AU13: =AT13+AS13*2^1+AR13*2^2+AQ13*2^3+AP13*2^4+AO13*2^5 -> 37 | AV13: =INDEX('Character Map'!A2:A65,AU13,1) -> Z
A14: 0 | B14: 0 | C14: 1 | D14: 1 | E14: 0 | F14: 0 | G14: =F14+E14*2^1+D14*2^2+C14*2^3+B14*2^4+A14*2^5 -> 12 | H14: =INDEX('Character Map'!A2:A65,G14,1) -> L | I14: 0 | J14: 1 | K14: 1 | L14: 0 | M14: 0 | N14: 0 | O14: =N14+M14*2^1+L14*2^2+K14*2^3+J14*2^4+I14*2^5 -> 24 | P14: =INDEX('Character Map'!A2:A65,O14,1) -> X | Q14: 1 | R14: 1 | S14: 0 | T14: 0 | U14: 0 | V14: 0 | W14: =V14+U14*2^1+T14*2^2+S14*2^3+R14*2^4+Q14*2^5 -> 48 | X14: =INDEX('Character Map'!A2:A65,W14,1) -> # | Y14: 1 | Z14: 0 | AA14: 0 | AB14: 0 | AC14: 0 | AD14: 1 | AE14: =AD14+AC14*2^1+AB14*2^2+AA14*2^3+Z14*2^4+Y14*2^5 -> 33 | AF14: =INDEX('Character Map'!A2:A65,AE14,1) -> 6 | AG14: 0 | AH14: 0 | AI14: 0 | AJ14: 0 | AK14: 1 | AL14: 1 | AM14: =AL14+AK14*2^1+AJ14*2^2+AI14*2^3+AH14*2^4+AG14*2^5 -> 3 | AN14: =INDEX('Character Map'!A2:A65,AM14,1) -> C | AO14: 0 | AP14: 0 | AQ14: 0 | AR14: 1 | AS14: 1 | AT14: 0 | AU14: =AT14+AS14*2^1+AR14*2^2+AQ14*2^3+AP14*2^4+AO14*2^5 -> 6 | AV14: =INDEX('Character Map'!A2:A65,AU14,1) -> F
A15: 0 | B15: 0 | C15: 1 | D15: 1 | E15: 0 | F15: 1 | G15: =F15+E15*2^1+D15*2^2+C15*2^3+B15*2^4+A15*2^5 -> 13 | H15: =INDEX('Character Map'!A2:A65,G15,1) -> M | I15: 0 | J15: 1 | K15: 1 | L15: 0 | M15: 1 | N15: 0 | O15: =N15+M15*2^1+L15*2^2+K15*2^3+J15*2^4+I15*2^5 -> 26 | P15: =INDEX('Character Map'!A2:A65,O15,1) -> Z | Q15: 1 | R15: 1 | S15: 0 | T15: 1 | U15: 0 | V15: 0 | W15: =V15+U15*2^1+T15*2^2+S15*2^3+R15*2^4+Q15*2^5 -> 52 | X15: =INDEX('Character Map'!A2:A65,W15,1) -> K | Y15: 1 | Z15: 0 | AA15: 1 | AB15: 0 | AC15: 0 | AD15: 1 | AE15: =AD15+AC15*2^1+AB15*2^2+AA15*2^3+Z15*2^4+Y15*2^5 -> 41 | AF15: =INDEX('Character Map'!A2:A65,AE15,1) -> V | AG15: 0 | AH15: 1 | AI15: 0 | AJ15: 0 | AK15: 1 | AL15: 1 | AM15: =AL15+AK15*2^1+AJ15*2^2+AI15*2^3+AH15*2^4+AG15*2^5 -> 19 | AN15: =INDEX('Character Map'!A2:A65,AM15,1) -> S | AO15: 1 | AP15: 0 | AQ15: 0 | AR15: 1 | AS15: 1 | AT15: 0 | AU15: =AT15+AS15*2^1+AR15*2^2+AQ15*2^3+AP15*2^4+AO15*2^5 -> 38 | AV15: =INDEX('Character Map'!A2:A65,AU15,1) -> Y
A16: 0 | B16: 0 | C16: 1 | D16: 1 | E16: 1 | F16: 0 | G16: =F16+E16*2^1+D16*2^2+C16*2^3+B16*2^4+A16*2^5 -> 14 | H16: =INDEX('Character Map'!A2:A65,G16,1) -> N | I16: 0 | J16: 1 | K16: 1 | L16: 1 | M16: 0 | N16: 0 | O16: =N16+M16*2^1+L16*2^2+K16*2^3+J16*2^4+I16*2^5 -> 28 | P16: =INDEX('Character Map'!A2:A65,O16,1) -> 1 | Q16: 1 | R16: 1 | S16: 1 | T16: 0 | U16: 0 | V16: 0 | W16: =V16+U16*2^1+T16*2^2+S16*2^3+R16*2^4+Q16*2^5 -> 56 | X16: =INDEX('Character Map'!A2:A65,W16,1) -> O | Y16: 1 | Z16: 1 | AA16: 0 | AB16: 0 | AC16: 0 | AD16: 1 | AE16: =AD16+AC16*2^1+AB16*2^2+AA16*2^3+Z16*2^4+Y16*2^5 -> 49 | AF16: =INDEX('Character Map'!A2:A65,AE16,1) -> 3 | AG16: 1 | AH16: 0 | AI16: 0 | AJ16: 0 | AK16: 1 | AL16: 1 | AM16: =AL16+AK16*2^1+AJ16*2^2+AI16*2^3+AH16*2^4+AG16*2^5 -> 35 | AN16: =INDEX('Character Map'!A2:A65,AM16,1) -> 8 | AO16: 0 | AP16: 0 | AQ16: 0 | AR16: 1 | AS16: 1 | AT16: 1 | AU16: =AT16+AS16*2^1+AR16*2^2+AQ16*2^3+AP16*2^4+AO16*2^5 -> 7 | AV16: =INDEX('Character Map'!A2:A65,AU16,1) -> G
A17: 0 | B17: 0 | C17: 1 | D17: 1 | E17: 1 | F17: 1 | G17: =F17+E17*2^1+D17*2^2+C17*2^3+B17*2^4+A17*2^5 -> 15 | H17: =INDEX('Character Map'!A2:A65,G17,1) -> O | I17: 0 | J17: 1 | K17: 1 | L17: 1 | M17: 1 | N17: 0 | O17: =N17+M17*2^1+L17*2^2+K17*2^3+J17*2^4+I17*2^5 -> 30 | P17: =INDEX('Character Map'!A2:A65,O17,1) -> 3 | Q17: 1 | R17: 1 | S17: 1 | T17: 1 | U17: 0 | V17: 0 | W17: =V17+U17*2^1+T17*2^2+S17*2^3+R17*2^4+Q17*2^5 -> 60 | X17: =INDEX('Character Map'!A2:A65,W17,1) -> 8 | Y17: 1 | Z17: 1 | AA17: 1 | AB17: 0 | AC17: 0 | AD17: 1 | AE17: =AD17+AC17*2^1+AB17*2^2+AA17*2^3+Z17*2^4+Y17*2^5 -> 57 | AF17: =INDEX('Character Map'!A2:A65,AE17,1) -> G | AG17: 1 | AH17: 1 | AI17: 0 | AJ17: 0 | AK17: 1 | AL17: 1 | AM17: =AL17+AK17*2^1+AJ17*2^2+AI17*2^3+AH17*2^4+AG17*2^5 -> 51 | AN17: =INDEX('Character Map'!A2:A65,AM17,1) -> N | AO17: 1 | AP17: 0 | AQ17: 0 | AR17: 1 | AS17: 1 | AT17: 1 | AU17: =AT17+AS17*2^1+AR17*2^2+AQ17*2^3+AP17*2^4+AO17*2^5 -> 39 | AV17: =INDEX('Character Map'!A2:A65,AU17,1) -> 1
A18: 0 | B18: 1 | C18: 0 | D18: 0 | E18: 0 | F18: 0 | G18: =F18+E18*2^1+D18*2^2+C18*2^3+B18*2^4+A18*2^5 -> 16 | H18: =INDEX('Character Map'!A2:A65,G18,1) -> P | I18: 1 | J18: 0 | K18: 0 | L18: 0 | M18: 0 | N18: 0 | O18: =N18+M18*2^1+L18*2^2+K18*2^3+J18*2^4+I18*2^5 -> 32 | P18: =INDEX('Character Map'!A2:A65,O18,1) -> 5 | Q18: 0 | R18: 0 | S18: 0 | T18: 0 | U18: 0 | V18: 1 | W18: =V18+U18*2^1+T18*2^2+S18*2^3+R18*2^4+Q18*2^5 -> 1 | X18: =INDEX('Character Map'!A2:A65,W18,1) -> A | Y18: 0 | Z18: 0 | AA18: 0 | AB18: 0 | AC18: 1 | AD18: 0 | AE18: =AD18+AC18*2^1+AB18*2^2+AA18*2^3+Z18*2^4+Y18*2^5 -> 2 | AF18: =INDEX('Character Map'!A2:A65,AE18,1) -> B | AG18: 0 | AH18: 0 | AI18: 0 | AJ18: 1 | AK18: 0 | AL18: 0 | AM18: =AL18+AK18*2^1+AJ18*2^2+AI18*2^3+AH18*2^4+AG18*2^5 -> 4 | AN18: =INDEX('Character Map'!A2:A65,AM18,1) -> D | AO18: 0 | AP18: 0 | AQ18: 1 | AR18: 0 | AS18: 0 | AT18: 0 | AU18: =AT18+AS18*2^1+AR18*2^2+AQ18*2^3+AP18*2^4+AO18*2^5 -> 8 | AV18: =INDEX('Character Map'!A2:A65,AU18,1) -> H
A19: 0 | B19: 1 | C19: 0 | D19: 0 | E19: 0 | F19: 1 | G19: =F19+E19*2^1+D19*2^2+C19*2^3+B19*2^4+A19*2^5 -> 17 | H19: =INDEX('Character Map'!A2:A65,G19,1) -> Q | I19: 1 | J19: 0 | K19: 0 | L19: 0 | M19: 1 | N19: 0 | O19: =N19+M19*2^1+L19*2^2+K19*2^3+J19*2^4+I19*2^5 -> 34 | P19: =INDEX('Character Map'!A2:A65,O19,1) -> 7 | Q19: 0 | R19: 0 | S19: 0 | T19: 1 | U19: 0 | V19: 1 | W19: =V19+U19*2^1+T19*2^2+S19*2^3+R19*2^4+Q19*2^5 -> 5 | X19: =INDEX('Character Map'!A2:A65,W19,1) -> E | Y19: 0 | Z19: 0 | AA19: 1 | AB19: 0 | AC19: 1 | AD19: 0 | AE19: =AD19+AC19*2^1+AB19*2^2+AA19*2^3+Z19*2^4+Y19*2^5 -> 10 | AF19: =INDEX('Character Map'!A2:A65,AE19,1) -> J | AG19: 0 | AH19: 1 | AI19: 0 | AJ19: 1 | AK19: 0 | AL19: 0 | AM19: =AL19+AK19*2^1+AJ19*2^2+AI19*2^3+AH19*2^4+AG19*2^5 -> 20 | AN19: =INDEX('Character Map'!A2:A65,AM19,1) -> T | AO19: 1 | AP19: 0 | AQ19: 1 | AR19: 0 | AS19: 0 | AT19: 0 | AU19: =AT19+AS19*2^1+AR19*2^2+AQ19*2^3+AP19*2^4+AO19*2^5 -> 40 | AV19: =INDEX('Character Map'!A2:A65,AU19,1) -> 4
A20: 0 | B20: 1 | C20: 0 | D20: 0 | E20: 1 | F20: 0 | G20: =F20+E20*2^1+D20*2^2+C20*2^3+B20*2^4+A20*2^5 -> 18 | H20: =INDEX('Character Map'!A2:A65,G20,1) -> R | I20: 1 | J20: 0 | K20: 0 | L20: 1 | M20: 0 | N20: 0 | O20: =N20+M20*2^1+L20*2^2+K20*2^3+J20*2^4+I20*2^5 -> 36 | P20: =INDEX('Character Map'!A2:A65,O20,1) -> 9 | Q20: 0 | R20: 0 | S20: 1 | T20: 0 | U20: 0 | V20: 1 | W20: =V20+U20*2^1+T20*2^2+S20*2^3+R20*2^4+Q20*2^5 -> 9 | X20: =INDEX('Character Map'!A2:A65,W20,1) -> I | Y20: 0 | Z20: 1 | AA20: 0 | AB20: 0 | AC20: 1 | AD20: 0 | AE20: =AD20+AC20*2^1+AB20*2^2+AA20*2^3+Z20*2^4+Y20*2^5 -> 18 | AF20: =INDEX('Character Map'!A2:A65,AE20,1) -> R | AG20: 1 | AH20: 0 | AI20: 0 | AJ20: 1 | AK20: 0 | AL20: 0 | AM20: =AL20+AK20*2^1+AJ20*2^2+AI20*2^3+AH20*2^4+AG20*2^5 -> 36 | AN20: =INDEX('Character Map'!A2:A65,AM20,1) -> 9 | AO20: 0 | AP20: 0 | AQ20: 1 | AR20: 0 | AS20: 0 | AT20: 1 | AU20: =AT20+AS20*2^1+AR20*2^2+AQ20*2^3+AP20*2^4+AO20*2^5 -> 9 | AV20: =INDEX('Character Map'!A2:A65,AU20,1) -> I
A21: 0 | B21: 1 | C21: 0 | D21: 0 | E21: 1 | F21: 1 | G21: =F21+E21*2^1+D21*2^2+C21*2^3+B21*2^4+A21*2^5 -> 19 | H21: =INDEX('Character Map'!A2:A65,G21,1) -> S | I21: 1 | J21: 0 | K21: 0 | L21: 1 | M21: 1 | N21: 0 | O21: =N21+M21*2^1+L21*2^2+K21*2^3+J21*2^4+I21*2^5 -> 38 | P21: =INDEX('Character Map'!A2:A65,O21,1) -> Y | Q21: 0 | R21: 0 | S21: 1 | T21: 1 | U21: 0 | V21: 1 | W21: =V21+U21*2^1+T21*2^2+S21*2^3+R21*2^4+Q21*2^5 -> 13 | X21: =INDEX('Character Map'!A2:A65,W21,1) -> M | Y21: 0 | Z21: 1 | AA21: 1 | AB21: 0 | AC21: 1 | AD21: 0 | AE21: =AD21+AC21*2^1+AB21*2^2+AA21*2^3+Z21*2^4+Y21*2^5 -> 26 | AF21: =INDEX('Character Map'!A2:A65,AE21,1) -> Z | AG21: 1 | AH21: 1 | AI21: 0 | AJ21: 1 | AK21: 0 | AL21: 0 | AM21: =AL21+AK21*2^1+AJ21*2^2+AI21*2^3+AH21*2^4+AG21*2^5 -> 52 | AN21: =INDEX('Character Map'!A2:A65,AM21,1) -> K | AO21: 1 | AP21: 0 | AQ21: 1 | AR21: 0 | AS21: 0 | AT21: 1 | AU21: =AT21+AS21*2^1+AR21*2^2+AQ21*2^3+AP21*2^4+AO21*2^5 -> 41 | AV21: =INDEX('Character Map'!A2:A65,AU21,1) -> V
A22: 0 | B22: 1 | C22: 0 | D22: 1 | E22: 0 | F22: 0 | G22: =F22+E22*2^1+D22*2^2+C22*2^3+B22*2^4+A22*2^5 -> 20 | H22: =INDEX('Character Map'!A2:A65,G22,1) -> T | I22: 1 | J22: 0 | K22: 1 | L22: 0 | M22: 0 | N22: 0 | O22: =N22+M22*2^1+L22*2^2+K22*2^3+J22*2^4+I22*2^5 -> 40 | P22: =INDEX('Character Map'!A2:A65,O22,1) -> 4 | Q22: 0 | R22: 1 | S22: 0 | T22: 0 | U22: 0 | V22: 1 | W22: =V22+U22*2^1+T22*2^2+S22*2^3+R22*2^4+Q22*2^5 -> 17 | X22: =INDEX('Character Map'!A2:A65,W22,1) -> Q | Y22: 1 | Z22: 0 | AA22: 0 | AB22: 0 | AC22: 1 | AD22: 0 | AE22: =AD22+AC22*2^1+AB22*2^2+AA22*2^3+Z22*2^4+Y22*2^5 -> 34 | AF22: =INDEX('Character Map'!A2:A65,AE22,1) -> 7 | AG22: 0 | AH22: 0 | AI22: 0 | AJ22: 1 | AK22: 0 | AL22: 1 | AM22: =AL22+AK22*2^1+AJ22*2^2+AI22*2^3+AH22*2^4+AG22*2^5 -> 5 | AN22: =INDEX('Character Map'!A2:A65,AM22,1) -> E | AO22: 0 | AP22: 0 | AQ22: 1 | AR22: 0 | AS22: 1 | AT22: 0 | AU22: =AT22+AS22*2^1+AR22*2^2+AQ22*2^3+AP22*2^4+AO22*2^5 -> 10 | AV22: =INDEX('Character Map'!A2:A65,AU22,1) -> J
A23: 0 | B23: 1 | C23: 0 | D23: 1 | E23: 0 | F23: 1 | G23: =F23+E23*2^1+D23*2^2+C23*2^3+B23*2^4+A23*2^5 -> 21 | H23: =INDEX('Character Map'!A2:A65,G23,1) -> U | I23: 1 | J23: 0 | K23: 1 | L23: 0 | M23: 1 | N23: 0 | O23: =N23+M23*2^1+L23*2^2+K23*2^3+J23*2^4+I23*2^5 -> 42 | P23: =INDEX('Character Map'!A2:A65,O23,1) -> U | Q23: 0 | R23: 1 | S23: 0 | T23: 1 | U23: 0 | V23: 1 | W23: =V23+U23*2^1+T23*2^2+S23*2^3+R23*2^4+Q23*2^5 -> 21 | X23: =INDEX('Character Map'!A2:A65,W23,1) -> U | Y23: 1 | Z23: 0 | AA23: 1 | AB23: 0 | AC23: 1 | AD23: 0 | AE23: =AD23+AC23*2^1+AB23*2^2+AA23*2^3+Z23*2^4+Y23*2^5 -> 42 | AF23: =INDEX('Character Map'!A2:A65,AE23,1) -> U | AG23: 0 | AH23: 1 | AI23: 0 | AJ23: 1 | AK23: 0 | AL23: 1 | AM23: =AL23+AK23*2^1+AJ23*2^2+AI23*2^3+AH23*2^4+AG23*2^5 -> 21 | AN23: =INDEX('Character Map'!A2:A65,AM23,1) -> U | AO23: 1 | AP23: 0 | AQ23: 1 | AR23: 0 | AS23: 1 | AT23: 0 | AU23: =AT23+AS23*2^1+AR23*2^2+AQ23*2^3+AP23*2^4+AO23*2^5 -> 42 | AV23: =INDEX('Character Map'!A2:A65,AU23,1) -> U
A24: 0 | B24: 1 | C24: 0 | D24: 1 | E24: 1 | F24: 0 | G24: =F24+E24*2^1+D24*2^2+C24*2^3+B24*2^4+A24*2^5 -> 22 | H24: =INDEX('Character Map'!A2:A65,G24,1) -> V | I24: 1 | J24: 0 | K24: 1 | L24: 1 | M24: 0 | N24: 0 | O24: =N24+M24*2^1+L24*2^2+K24*2^3+J24*2^4+I24*2^5 -> 44 | P24: =INDEX('Character Map'!A2:A65,O24,1) -> S | Q24: 0 | R24: 1 | S24: 1 | T24: 0 | U24: 0 | V24: 1 | W24: =V24+U24*2^1+T24*2^2+S24*2^3+R24*2^4+Q24*2^5 -> 25 | X24: =INDEX('Character Map'!A2:A65,W24,1) -> Y | Y24: 1 | Z24: 1 | AA24: 0 | AB24: 0 | AC24: 1 | AD24: 0 | AE24: =AD24+AC24*2^1+AB24*2^2+AA24*2^3+Z24*2^4+Y24*2^5 -> 50 | AF24: =INDEX('Character Map'!A2:A65,AE24,1) -> M | AG24: 1 | AH24: 0 | AI24: 0 | AJ24: 1 | AK24: 0 | AL24: 1 | AM24: =AL24+AK24*2^1+AJ24*2^2+AI24*2^3+AH24*2^4+AG24*2^5 -> 37 | AN24: =INDEX('Character Map'!A2:A65,AM24,1) -> Z | AO24: 0 | AP24: 0 | AQ24: 1 | AR24: 0 | AS24: 1 | AT24: 1 | AU24: =AT24+AS24*2^1+AR24*2^2+AQ24*2^3+AP24*2^4+AO24*2^5 -> 11 | AV24: =INDEX('Character Map'!A2:A65,AU24,1) -> K
A25: 0 | B25: 1 | C25: 0 | D25: 1 | E25: 1 | F25: 1 | G25: =F25+E25*2^1+D25*2^2+C25*2^3+B25*2^4+A25*2^5 -> 23 | H25: =INDEX('Character Map'!A2:A65,G25,1) -> W | I25: 1 | J25: 0 | K25: 1 | L25: 1 | M25: 1 | N25: 0 | O25: =N25+M25*2^1+L25*2^2+K25*2^3+J25*2^4+I25*2^5 -> 46 | P25: =INDEX('Character Map'!A2:A65,O25,1) -> 2 | Q25: 0 | R25: 1 | S25: 1 | T25: 1 | U25: 0 | V25: 1 | W25: =V25+U25*2^1+T25*2^2+S25*2^3+R25*2^4+Q25*2^5 -> 29 | X25: =INDEX('Character Map'!A2:A65,W25,1) -> 2 | Y25: 1 | Z25: 1 | AA25: 1 | AB25: 0 | AC25: 1 | AD25: 0 | AE25: =AD25+AC25*2^1+AB25*2^2+AA25*2^3+Z25*2^4+Y25*2^5 -> 58 | AF25: =INDEX('Character Map'!A2:A65,AE25,1) -> # | AG25: 1 | AH25: 1 | AI25: 0 | AJ25: 1 | AK25: 0 | AL25: 1 | AM25: =AL25+AK25*2^1+AJ25*2^2+AI25*2^3+AH25*2^4+AG25*2^5 -> 53 | AN25: =INDEX('Character Map'!A2:A65,AM25,1) -> # | AO25: 1 | AP25: 0 | AQ25: 1 | AR25: 0 | AS25: 1 | AT25: 1 | AU25: =AT25+AS25*2^1+AR25*2^2+AQ25*2^3+AP25*2^4+AO25*2^5 -> 43 | AV25: =INDEX('Character Map'!A2:A65,AU25,1) -> W
A26: 0 | B26: 1 | C26: 1 | D26: 0 | E26: 0 | F26: 0 | G26: =F26+E26*2^1+D26*2^2+C26*2^3+B26*2^4+A26*2^5 -> 24 | H26: =INDEX('Character Map'!A2:A65,G26,1) -> X | I26: 1 | J26: 1 | K26: 0 | L26: 0 | M26: 0 | N26: 0 | O26: =N26+M26*2^1+L26*2^2+K26*2^3+J26*2^4+I26*2^5 -> 48 | P26: =INDEX('Character Map'!A2:A65,O26,1) -> # | Q26: 1 | R26: 0 | S26: 0 | T26: 0 | U26: 0 | V26: 1 | W26: =V26+U26*2^1+T26*2^2+S26*2^3+R26*2^4+Q26*2^5 -> 33 | X26: =INDEX('Character Map'!A2:A65,W26,1) -> 6 | Y26: 0 | Z26: 0 | AA26: 0 | AB26: 0 | AC26: 1 | AD26: 1 | AE26: =AD26+AC26*2^1+AB26*2^2+AA26*2^3+Z26*2^4+Y26*2^5 -> 3 | AF26: =INDEX('Character Map'!A2:A65,AE26,1) -> C | AG26: 0 | AH26: 0 | AI26: 0 | AJ26: 1 | AK26: 1 | AL26: 0 | AM26: =AL26+AK26*2^1+AJ26*2^2+AI26*2^3+AH26*2^4+AG26*2^5 -> 6 | AN26: =INDEX('Character Map'!A2:A65,AM26,1) -> F | AO26: 0 | AP26: 0 | AQ26: 1 | AR26: 1 | AS26: 0 | AT26: 0 | AU26: =AT26+AS26*2^1+AR26*2^2+AQ26*2^3+AP26*2^4+AO26*2^5 -> 12 | AV26: =INDEX('Character Map'!A2:A65,AU26,1) -> L
A27: 0 | B27: 1 | C27: 1 | D27: 0 | E27: 0 | F27: 1 | G27: =F27+E27*2^1+D27*2^2+C27*2^3+B27*2^4+A27*2^5 -> 25 | H27: =INDEX('Character Map'!A2:A65,G27,1) -> Y | I27: 1 | J27: 1 | K27: 0 | L27: 0 | M27: 1 | N27: 0 | O27: =N27+M27*2^1+L27*2^2+K27*2^3+J27*2^4+I27*2^5 -> 50 | P27: =INDEX('Character Map'!A2:A65,O27,1) -> M | Q27: 1 | R27: 0 | S27: 0 | T27: 1 | U27: 0 | V27: 1 | W27: =V27+U27*2^1+T27*2^2+S27*2^3+R27*2^4+Q27*2^5 -> 37 | X27: =INDEX('Character Map'!A2:A65,W27,1) -> Z | Y27: 0 | Z27: 0 | AA27: 1 | AB27: 0 | AC27: 1 | AD27: 1 | AE27: =AD27+AC27*2^1+AB27*2^2+AA27*2^3+Z27*2^4+Y27*2^5 -> 11 | AF27: =INDEX('Character Map'!A2:A65,AE27,1) -> K | AG27: 0 | AH27: 1 | AI27: 0 | AJ27: 1 | AK27: 1 | AL27: 0 | AM27: =AL27+AK27*2^1+AJ27*2^2+AI27*2^3+AH27*2^4+AG27*2^5 -> 22 | AN27: =INDEX('Character Map'!A2:A65,AM27,1) -> V | AO27: 1 | AP27: 0 | AQ27: 1 | AR27: 1 | AS27: 0 | AT27: 0 | AU27: =AT27+AS27*2^1+AR27*2^2+AQ27*2^3+AP27*2^4+AO27*2^5 -> 44 | AV27: =INDEX('Character Map'!A2:A65,AU27,1) -> S
A28: 0 | B28: 1 | C28: 1 | D28: 0 | E28: 1 | F28: 0 | G28: =F28+E28*2^1+D28*2^2+C28*2^3+B28*2^4+A28*2^5 -> 26 | H28: =INDEX('Character Map'!A2:A65,G28,1) -> Z | I28: 1 | J28: 1 | K28: 0 | L28: 1 | M28: 0 | N28: 0 | O28: =N28+M28*2^1+L28*2^2+K28*2^3+J28*2^4+I28*2^5 -> 52 | P28: =INDEX('Character Map'!A2:A65,O28,1) -> K | Q28: 1 | R28: 0 | S28: 1 | T28: 0 | U28: 0 | V28: 1 | W28: =V28+U28*2^1+T28*2^2+S28*2^3+R28*2^4+Q28*2^5 -> 41 | X28: =INDEX('Character Map'!A2:A65,W28,1) -> V | Y28: 0 | Z28: 1 | AA28: 0 | AB28: 0 | AC28: 1 | AD28: 1 | AE28: =AD28+AC28*2^1+AB28*2^2+AA28*2^3+Z28*2^4+Y28*2^5 -> 19 | AF28: =INDEX('Character Map'!A2:A65,AE28,1) -> S | AG28: 1 | AH28: 0 | AI28: 0 | AJ28: 1 | AK28: 1 | AL28: 0 | AM28: =AL28+AK28*2^1+AJ28*2^2+AI28*2^3+AH28*2^4+AG28*2^5 -> 38 | AN28: =INDEX('Character Map'!A2:A65,AM28,1) -> Y | AO28: 0 | AP28: 0 | AQ28: 1 | AR28: 1 | AS28: 0 | AT28: 1 | AU28: =AT28+AS28*2^1+AR28*2^2+AQ28*2^3+AP28*2^4+AO28*2^5 -> 13 | AV28: =INDEX('Character Map'!A2:A65,AU28,1) -> M
A29: 0 | B29: 1 | C29: 1 | D29: 0 | E29: 1 | F29: 1 | G29: =F29+E29*2^1+D29*2^2+C29*2^3+B29*2^4+A29*2^5 -> 27 | H29: =INDEX('Character Map'!A2:A65,G29,1) -> 0 | I29: 1 | J29: 1 | K29: 0 | L29: 1 | M29: 1 | N29: 0 | O29: =N29+M29*2^1+L29*2^2+K29*2^3+J29*2^4+I29*2^5 -> 54 | P29: =INDEX('Character Map'!A2:A65,O29,1) -> # | Q29: 1 | R29: 0 | S29: 1 | T29: 1 | U29: 0 | V29: 1 | W29: =V29+U29*2^1+T29*2^2+S29*2^3+R29*2^4+Q29*2^5 -> 45 | X29: =INDEX('Character Map'!A2:A65,W29,1) -> 0 | Y29: 0 | Z29: 1 | AA29: 1 | AB29: 0 | AC29: 1 | AD29: 1 | AE29: =AD29+AC29*2^1+AB29*2^2+AA29*2^3+Z29*2^4+Y29*2^5 -> 27 | AF29: =INDEX('Character Map'!A2:A65,AE29,1) -> 0 | AG29: 1 | AH29: 1 | AI29: 0 | AJ29: 1 | AK29: 1 | AL29: 0 | AM29: =AL29+AK29*2^1+AJ29*2^2+AI29*2^3+AH29*2^4+AG29*2^5 -> 54 | AN29: =INDEX('Character Map'!A2:A65,AM29,1) -> # | AO29: 1 | AP29: 0 | AQ29: 1 | AR29: 1 | AS29: 0 | AT29: 1 | AU29: =AT29+AS29*2^1+AR29*2^2+AQ29*2^3+AP29*2^4+AO29*2^5 -> 45 | AV29: =INDEX('Character Map'!A2:A65,AU29,1) -> 0
A30: 0 | B30: 1 | C30: 1 | D30: 1 | E30: 0 | F30: 0 | G30: =F30+E30*2^1+D30*2^2+C30*2^3+B30*2^4+A30*2^5 -> 28 | H30: =INDEX('Character Map'!A2:A65,G30,1) -> 1 | I30: 1 | J30: 1 | K30: 1 | L30: 0 | M30: 0 | N30: 0 | O30: =N30+M30*2^1+L30*2^2+K30*2^3+J30*2^4+I30*2^5 -> 56 | P30: =INDEX('Character Map'!A2:A65,O30,1) -> O | Q30: 1 | R30: 1 | S30: 0 | T30: 0 | U30: 0 | V30: 1 | W30: =V30+U30*2^1+T30*2^2+S30*2^3+R30*2^4+Q30*2^5 -> 49 | X30: =INDEX('Character Map'!A2:A65,W30,1) -> 3 | Y30: 1 | Z30: 0 | AA30: 0 | AB30: 0 | AC30: 1 | AD30: 1 | AE30: =AD30+AC30*2^1+AB30*2^2+AA30*2^3+Z30*2^4+Y30*2^5 -> 35 | AF30: =INDEX('Character Map'!A2:A65,AE30,1) -> 8 | AG30: 0 | AH30: 0 | AI30: 0 | AJ30: 1 | AK30: 1 | AL30: 1 | AM30: =AL30+AK30*2^1+AJ30*2^2+AI30*2^3+AH30*2^4+AG30*2^5 -> 7 | AN30: =INDEX('Character Map'!A2:A65,AM30,1) -> G | AO30: 0 | AP30: 0 | AQ30: 1 | AR30: 1 | AS30: 1 | AT30: 0 | AU30: =AT30+AS30*2^1+AR30*2^2+AQ30*2^3+AP30*2^4+AO30*2^5 -> 14 | AV30: =INDEX('Character Map'!A2:A65,AU30,1) -> N
A31: 0 | B31: 1 | C31: 1 | D31: 1 | E31: 0 | F31: 1 | G31: =F31+E31*2^1+D31*2^2+C31*2^3+B31*2^4+A31*2^5 -> 29 | H31: =INDEX('Character Map'!A2:A65,G31,1) -> 2 | I31: 1 | J31: 1 | K31: 1 | L31: 0 | M31: 1 | N31: 0 | O31: =N31+M31*2^1+L31*2^2+K31*2^3+J31*2^4+I31*2^5 -> 58 | P31: =INDEX('Character Map'!A2:A65,O31,1) -> # | Q31: 1 | R31: 1 | S31: 0 | T31: 1 | U31: 0 | V31: 1 | W31: =V31+U31*2^1+T31*2^2+S31*2^3+R31*2^4+Q31*2^5 -> 53 | X31: =INDEX('Character Map'!A2:A65,W31,1) -> # | Y31: 1 | Z31: 0 | AA31: 1 | AB31: 0 | AC31: 1 | AD31: 1 | AE31: =AD31+AC31*2^1+AB31*2^2+AA31*2^3+Z31*2^4+Y31*2^5 -> 43 | AF31: =INDEX('Character Map'!A2:A65,AE31,1) -> W | AG31: 0 | AH31: 1 | AI31: 0 | AJ31: 1 | AK31: 1 | AL31: 1 | AM31: =AL31+AK31*2^1+AJ31*2^2+AI31*2^3+AH31*2^4+AG31*2^5 -> 23 | AN31: =INDEX('Character Map'!A2:A65,AM31,1) -> W | AO31: 1 | AP31: 0 | AQ31: 1 | AR31: 1 | AS31: 1 | AT31: 0 | AU31: =AT31+AS31*2^1+AR31*2^2+AQ31*2^3+AP31*2^4+AO31*2^5 -> 46 | AV31: =INDEX('Character Map'!A2:A65,AU31,1) -> 2
A32: 0 | B32: 1 | C32: 1 | D32: 1 | E32: 1 | F32: 0 | G32: =F32+E32*2^1+D32*2^2+C32*2^3+B32*2^4+A32*2^5 -> 30 | H32: =INDEX('Character Map'!A2:A65,G32,1) -> 3 | I32: 1 | J32: 1 | K32: 1 | L32: 1 | M32: 0 | N32: 0 | O32: =N32+M32*2^1+L32*2^2+K32*2^3+J32*2^4+I32*2^5 -> 60 | P32: =INDEX('Character Map'!A2:A65,O32,1) -> 8 | Q32: 1 | R32: 1 | S32: 1 | T32: 0 | U32: 0 | V32: 1 | W32: =V32+U32*2^1+T32*2^2+S32*2^3+R32*2^4+Q32*2^5 -> 57 | X32: =INDEX('Character Map'!A2:A65,W32,1) -> G | Y32: 1 | Z32: 1 | AA32: 0 | AB32: 0 | AC32: 1 | AD32: 1 | AE32: =AD32+AC32*2^1+AB32*2^2+AA32*2^3+Z32*2^4+Y32*2^5 -> 51 | AF32: =INDEX('Character Map'!A2:A65,AE32,1) -> N | AG32: 1 | AH32: 0 | AI32: 0 | AJ32: 1 | AK32: 1 | AL32: 1 | AM32: =AL32+AK32*2^1+AJ32*2^2+AI32*2^3+AH32*2^4+AG32*2^5 -> 39 | AN32: =INDEX('Character Map'!A2:A65,AM32,1) -> 1 | AO32: 0 | AP32: 0 | AQ32: 1 | AR32: 1 | AS32: 1 | AT32: 1 | AU32: =AT32+AS32*2^1+AR32*2^2+AQ32*2^3+AP32*2^4+AO32*2^5 -> 15 | AV32: =INDEX('Character Map'!A2:A65,AU32,1) -> O
A33: 0 | B33: 1 | C33: 1 | D33: 1 | E33: 1 | F33: 1 | G33: =F33+E33*2^1+D33*2^2+C33*2^3+B33*2^4+A33*2^5 -> 31 | H33: =INDEX('Character Map'!A2:A65,G33,1) -> 4 | I33: 1 | J33: 1 | K33: 1 | L33: 1 | M33: 1 | N33: 0 | O33: =N33+M33*2^1+L33*2^2+K33*2^3+J33*2^4+I33*2^5 -> 62 | P33: =INDEX('Character Map'!A2:A65,O33,1) -> 6 | Q33: 1 | R33: 1 | S33: 1 | T33: 1 | U33: 0 | V33: 1 | W33: =V33+U33*2^1+T33*2^2+S33*2^3+R33*2^4+Q33*2^5 -> 61 | X33: =INDEX('Character Map'!A2:A65,W33,1) -> 7 | Y33: 1 | Z33: 1 | AA33: 1 | AB33: 0 | AC33: 1 | AD33: 1 | AE33: =AD33+AC33*2^1+AB33*2^2+AA33*2^3+Z33*2^4+Y33*2^5 -> 59 | AF33: =INDEX('Character Map'!A2:A65,AE33,1) -> E | AG33: 1 | AH33: 1 | AI33: 0 | AJ33: 1 | AK33: 1 | AL33: 1 | AM33: =AL33+AK33*2^1+AJ33*2^2+AI33*2^3+AH33*2^4+AG33*2^5 -> 55 | AN33: =INDEX('Character Map'!A2:A65,AM33,1) -> J | AO33: 1 | AP33: 0 | AQ33: 1 | AR33: 1 | AS33: 1 | AT33: 1 | AU33: =AT33+AS33*2^1+AR33*2^2+AQ33*2^3+AP33*2^4+AO33*2^5 -> 47 | AV33: =INDEX('Character Map'!A2:A65,AU33,1) -> T
A34: 1 | B34: 0 | C34: 0 | D34: 0 | E34: 0 | F34: 0 | G34: =F34+E34*2^1+D34*2^2+C34*2^3+B34*2^4+A34*2^5 -> 32 | H34: =INDEX('Character Map'!A2:A65,G34,1) -> 5 | I34: 0 | J34: 0 | K34: 0 | L34: 0 | M34: 0 | N34: 1 | O34: =N34+M34*2^1+L34*2^2+K34*2^3+J34*2^4+I34*2^5 -> 1 | P34: =INDEX('Character Map'!A2:A65,O34,1) -> A | Q34: 0 | R34: 0 | S34: 0 | T34: 0 | U34: 1 | V34: 0 | W34: =V34+U34*2^1+T34*2^2+S34*2^3+R34*2^4+Q34*2^5 -> 2 | X34: =INDEX('Character Map'!A2:A65,W34,1) -> B | Y34: 0 | Z34: 0 | AA34: 0 | AB34: 1 | AC34: 0 | AD34: 0 | AE34: =AD34+AC34*2^1+AB34*2^2+AA34*2^3+Z34*2^4+Y34*2^5 -> 4 | AF34: =INDEX('Character Map'!A2:A65,AE34,1) -> D | AG34: 0 | AH34: 0 | AI34: 1 | AJ34: 0 | AK34: 0 | AL34: 0 | AM34: =AL34+AK34*2^1+AJ34*2^2+AI34*2^3+AH34*2^4+AG34*2^5 -> 8 | AN34: =INDEX('Character Map'!A2:A65,AM34,1) -> H | AO34: 0 | AP34: 1 | AQ34: 0 | AR34: 0 | AS34: 0 | AT34: 0 | AU34: =AT34+AS34*2^1+AR34*2^2+AQ34*2^3+AP34*2^4+AO34*2^5 -> 16 | AV34: =INDEX('Character Map'!A2:A65,AU34,1) -> P
A35: 1 | B35: 0 | C35: 0 | D35: 0 | E35: 0 | F35: 1 | G35: =F35+E35*2^1+D35*2^2+C35*2^3+B35*2^4+A35*2^5 -> 33 | H35: =INDEX('Character Map'!A2:A65,G35,1) -> 6 | I35: 0 | J35: 0 | K35: 0 | L35: 0 | M35: 1 | N35: 1 | O35: =N35+M35*2^1+L35*2^2+K35*2^3+J35*2^4+I35*2^5 -> 3 | P35: =INDEX('Character Map'!A2:A65,O35,1) -> C | Q35: 0 | R35: 0 | S35: 0 | T35: 1 | U35: 1 | V35: 0 | W35: =V35+U35*2^1+T35*2^2+S35*2^3+R35*2^4+Q35*2^5 -> 6 | X35: =INDEX('Character Map'!A2:A65,W35,1) -> F | Y35: 0 | Z35: 0 | AA35: 1 | AB35: 1 | AC35: 0 | AD35: 0 | AE35: =AD35+AC35*2^1+AB35*2^2+AA35*2^3+Z35*2^4+Y35*2^5 -> 12 | AF35: =INDEX('Character Map'!A2:A65,AE35,1) -> L | AG35: 0 | AH35: 1 | AI35: 1 | AJ35: 0 | AK35: 0 | AL35: 0 | AM35: =AL35+AK35*2^1+AJ35*2^2+AI35*2^3+AH35*2^4+AG35*2^5 -> 24 | AN35: =INDEX('Character Map'!A2:A65,AM35,1) -> X | AO35: 1 | AP35: 1 | AQ35: 0 | AR35: 0 | AS35: 0 | AT35: 0 | AU35: =AT35+AS35*2^1+AR35*2^2+AQ35*2^3+AP35*2^4+AO35*2^5 -> 48 | AV35: =INDEX('Character Map'!A2:A65,AU35,1) -> #
A36: 1 | B36: 0 | C36: 0 | D36: 0 | E36: 1 | F36: 0 | G36: =F36+E36*2^1+D36*2^2+C36*2^3+B36*2^4+A36*2^5 -> 34 | H36: =INDEX('Character Map'!A2:A65,G36,1) -> 7 | I36: 0 | J36: 0 | K36: 0 | L36: 1 | M36: 0 | N36: 1 | O36: =N36+M36*2^1+L36*2^2+K36*2^3+J36*2^4+I36*2^5 -> 5 | P36: =INDEX('Character Map'!A2:A65,O36,1) -> E | Q36: 0 | R36: 0 | S36: 1 | T36: 0 | U36: 1 | V36: 0 | W36: =V36+U36*2^1+T36*2^2+S36*2^3+R36*2^4+Q36*2^5 -> 10 | X36: =INDEX('Character Map'!A2:A65,W36,1) -> J | Y36: 0 | Z36: 1 | AA36: 0 | AB36: 1 | AC36: 0 | AD36: 0 | AE36: =AD36+AC36*2^1+AB36*2^2+AA36*2^3+Z36*2^4+Y36*2^5 -> 20 | AF36: =INDEX('Character Map'!A2:A65,AE36,1) -> T | AG36: 1 | AH36: 0 | AI36: 1 | AJ36: 0 | AK36: 0 | AL36: 0 | AM36: =AL36+AK36*2^1+AJ36*2^2+AI36*2^3+AH36*2^4+AG36*2^5 -> 40 | AN36: =INDEX('Character Map'!A2:A65,AM36,1) -> 4 | AO36: 0 | AP36: 1 | AQ36: 0 | AR36: 0 | AS36: 0 | AT36: 1 | AU36: =AT36+AS36*2^1+AR36*2^2+AQ36*2^3+AP36*2^4+AO36*2^5 -> 17 | AV36: =INDEX('Character Map'!A2:A65,AU36,1) -> Q
A37: 1 | B37: 0 | C37: 0 | D37: 0 | E37: 1 | F37: 1 | G37: =F37+E37*2^1+D37*2^2+C37*2^3+B37*2^4+A37*2^5 -> 35 | H37: =INDEX('Character Map'!A2:A65,G37,1) -> 8 | I37: 0 | J37: 0 | K37: 0 | L37: 1 | M37: 1 | N37: 1 | O37: =N37+M37*2^1+L37*2^2+K37*2^3+J37*2^4+I37*2^5 -> 7 | P37: =INDEX('Character Map'!A2:A65,O37,1) -> G | Q37: 0 | R37: 0 | S37: 1 | T37: 1 | U37: 1 | V37: 0 | W37: =V37+U37*2^1+T37*2^2+S37*2^3+R37*2^4+Q37*2^5 -> 14 | X37: =INDEX('Character Map'!A2:A65,W37,1) -> N | Y37: 0 | Z37: 1 | AA37: 1 | AB37: 1 | AC37: 0 | AD37: 0 | AE37: =AD37+AC37*2^1+AB37*2^2+AA37*2^3+Z37*2^4+Y37*2^5 -> 28 | AF37: =INDEX('Character Map'!A2:A65,AE37,1) -> 1 | AG37: 1 | AH37: 1 | AI37: 1 | AJ37: 0 | AK37: 0 | AL37: 0 | AM37: =AL37+AK37*2^1+AJ37*2^2+AI37*2^3+AH37*2^4+AG37*2^5 -> 56 | AN37: =INDEX('Character Map'!A2:A65,AM37,1) -> O | AO37: 1 | AP37: 1 | AQ37: 0 | AR37: 0 | AS37: 0 | AT37: 1 | AU37: =AT37+AS37*2^1+AR37*2^2+AQ37*2^3+AP37*2^4+AO37*2^5 -> 49 | AV37: =INDEX('Character Map'!A2:A65,AU37,1) -> 3
A38: 1 | B38: 0 | C38: 0 | D38: 1 | E38: 0 | F38: 0 | G38: =F38+E38*2^1+D38*2^2+C38*2^3+B38*2^4+A38*2^5 -> 36 | H38: =INDEX('Character Map'!A2:A65,G38,1) -> 9 | I38: 0 | J38: 0 | K38: 1 | L38: 0 | M38: 0 | N38: 1 | O38: =N38+M38*2^1+L38*2^2+K38*2^3+J38*2^4+I38*2^5 -> 9 | P38: =INDEX('Character Map'!A2:A65,O38,1) -> I | Q38: 0 | R38: 1 | S38: 0 | T38: 0 | U38: 1 | V38: 0 | W38: =V38+U38*2^1+T38*2^2+S38*2^3+R38*2^4+Q38*2^5 -> 18 | X38: =INDEX('Character Map'!A2:A65,W38,1) -> R | Y38: 1 | Z38: 0 | AA38: 0 | AB38: 1 | AC38: 0 | AD38: 0 | AE38: =AD38+AC38*2^1+AB38*2^2+AA38*2^3+Z38*2^4+Y38*2^5 -> 36 | AF38: =INDEX('Character Map'!A2:A65,AE38,1) -> 9 | AG38: 0 | AH38: 0 | AI38: 1 | AJ38: 0 | AK38: 0 | AL38: 1 | AM38: =AL38+AK38*2^1+AJ38*2^2+AI38*2^3+AH38*2^4+AG38*2^5 -> 9 | AN38: =INDEX('Character Map'!A2:A65,AM38,1) -> I | AO38: 0 | AP38: 1 | AQ38: 0 | AR38: 0 | AS38: 1 | AT38: 0 | AU38: =AT38+AS38*2^1+AR38*2^2+AQ38*2^3+AP38*2^4+AO38*2^5 -> 18 | AV38: =INDEX('Character Map'!A2:A65,AU38,1) -> R

Sheet Character Map
A1: Map | B1: Index | C1: A | D1: B | E1: C | F1: D | G1: E | H1: F | I1: G | J1: H | K1: I | L1: J | M1: K | N1: L | O1: M | P1: N | Q1: O | R1: P | S1: Q | T1: R | U1: S | V1: T | W1: U | X1: V | Y1: W | Z1: X | AA1: Y | AB1: Z | AC1: 0 | AD1: 1 | AE1: 2 | AF1: 3 | AG1: 4 | AH1: 5 | AI1: 6 | AJ1: 7 | AK1: 8 | AL1: 9 | AM1: Options Seen
A2: A | B2: 1 | D2: X | E2: X | F2: X | G2: X | H2: X | I2: X | J2: X | K2: X | L2: X | M2: X | N2: X | O2: X | P2: X | Q2: X | R2: X | S2: X | T2: X | U2: X | V2: X | W2: X | X2: X | Y2: X | Z2: X | AA2: X | AB2: X | AC2: X | AD2: X | AE2: X | AF2: X | AG2: X | AH2: X | AI2: X | AJ2: X | AK2: X | AL2: X | AM2: 1,2,3,4,5,6 | AN2: X
A3: B | B3: 2 | C3: X | E3: X | F3: X | G3: X | H3: X | I3: X | J3: X | K3: X | L3: X | M3: X | N3: X | O3: X | P3: X | Q3: X | R3: X | S3: X | T3: X | U3: X | V3: X | W3: X | X3: X | Y3: X | Z3: X | AA3: X | AB3: X | AC3: X | AD3: X | AE3: X | AF3: X | AG3: X | AH3: X | AI3: X | AJ3: X | AK3: X | AL3: X | AM3: 1,2,3,4,5,6 | AN3: X
A4: C | B4: 3 | C4: X | D4: X | F4: X | G4: X | H4: X | I4: X | J4: X | K4: X | L4: X | M4: X | N4: X | O4: X | P4: X | Q4: X | R4: X | S4: X | T4: X | U4: X | V4: X | W4: X | X4: X | Y4: X | Z4: X | AA4: X | AB4: X | AC4: X | AD4: X | AE4: X | AF4: X | AG4: X | AH4: X | AI4: X | AJ4: X | AK4: X | AL4: X | AM4: 1,2,4,5,6 | AN4: 61
A5: D | B5: 4 | C5: X | D5: X | E5: X | G5: X | H5: X | I5: X | J5: X | K5: X | L5: X | M5: X | N5: X | O5: X | P5: X | Q5: X | R5: X | S5: X | T5: X | U5: X | V5: X | W5: X | X5: X | Y5: X | Z5: X | AA5: X | AB5: X | AC5: X | AD5: X | AE5: X | AF5: X | AG5: X | AH5: X | AI5: X | AJ5: X | AK5: X | AL5: X | AM5: 1,2,3,4,5,6 | AN5: X
A6: E | B6: 5 | C6: X | D6: X | E6: X | F6: X | H6: X | I6: X | J6: X | K6: X | L6: X | M6: X | N6: X | O6: X | P6: X | Q6: X | R6: X | S6: X | T6: X | U6: X | V6: X | W6: X | X6: X | Y6: X | Z6: X | AA6: X | AB6: X | AC6: X | AD6: X | AE6: X | AF6: X | AG6: X | AH6: X | AI6: X | AJ6: X | AK6: X | AL6: X | AM6: 1,2,3,5,6 | AN6: 59
A7: F | B7: 6 | C7: X | D7: X | E7: X | F7: X | G7: X | I7: X | J7: X | K7: X | L7: X | M7: X | N7: X | O7: X | P7: X | Q7: X | R7: X | S7: X | T7: X | U7: X | V7: X | W7: X | X7: X | Y7: X | Z7: X | AA7: X | AB7: X | AC7: X | AD7: X | AE7: X | AF7: X | AG7: X | AH7: X | AI7: X | AJ7: X | AK7: X | AL7: X | AM7: 1,2,3,5,6 | AN7: 59
A8: G | B8: 7 | C8: X | D8: X | E8: X | F8: X | G8: X | H8: X | J8: X | K8: X | L8: X | M8: X | N8: X | O8: X | P8: X | Q8: X | R8: X | S8: X | T8: X | U8: X | V8: X | W8: X | X8: X | Y8: X | Z8: X | AA8: X | AB8: X | AC8: X | AD8: X | AE8: X | AF8: X | AG8: X | AH8: X | AI8: X | AJ8: X | AK8: X | AL8: X | AM8: 1,2,5,6 | AN8: 57
A9: H | B9: 8 | C9: X | D9: X | E9: X | F9: X | G9: X | H9: X | I9: X | K9: X | L9: X | M9: X | N9: X | O9: X | P9: X | Q9: X | R9: X | S9: X | T9: X | U9: X | V9: X | W9: X | X9: X | Y9: X | Z9: X | AA9: X | AB9: X | AC9: X | AD9: X | AE9: X | AF9: X | AG9: X | AH9: X | AI9: X | AJ9: X | AK9: X | AL9: X | AM9: 1,2,3,4,5,6 | AN9: X
A10: I | B10: 9 | C10: X | D10: X | E10: X | F10: X | G10: X | H10: X | I10: X | J10: X | L10: X | M10: X | N10: X | O10: X | P10: X | Q10: X | R10: X | S10: X | T10: X | U10: X | V10: X | W10: X | X10: X | Y10: X | Z10: X | AA10: X | AB10: X | AC10: X | AD10: X | AE10: X | AF10: X | AG10: X | AH10: X | AI10: X | AJ10: X | AK10: X | AL10: X | AM10: 1,2,3,4,5,6 | AN10: X
A11: J | B11: 10 | C11: X | D11: X | E11: X | F11: X | G11: X | H11: X | I11: X | J11: X | K11: X | M11: X | N11: X | O11: X | P11: X | Q11: X | R11: X | S11: X | T11: X | U11: X | V11: X | W11: X | X11: X | Y11: X | Z11: X | AA11: X | AB11: X | AC11: X | AD11: X | AE11: X | AF11: X | AG11: X | AH11: X | AI11: X | AJ11: X | AK11: X | AL11: X | AM11: 1,2,3,4,6 | AN11: 55
A12: K | B12: 11 | C12: X | D12: X | E12: X | F12: X | G12: X | H12: X | I12: X | J12: X | K12: X | L12: X | N12: X | O12: X | P12: X | Q12: X | R12: X | S12: X | T12: X | U12: X | V12: X | W12: X | X12: X | Y12: X | Z12: X | AA12: X | AB12: X | AC12: X | AD12: X | AE12: X | AF12: X | AG12: X | AH12: X | AI12: X | AJ12: X | AK12: X | AL12: X | AM12: 1,4,6 | AN12: 52
A13: L | B13: 12 | C13: X | D13: X | E13: X | F13: X | G13: X | H13: X | I13: X | J13: X | K13: X | L13: X | M13: X | O13: X | P13: X | Q13: X | R13: X | S13: X | T13: X | U13: X | V13: X | W13: X | X13: X | Y13: X | Z13: X | AA13: X | AB13: X | AC13: X | AD13: X | AE13: X | AF13: X | AG13: X | AH13: X | AI13: X | AJ13: X | AK13: X | AL13: X | AM13: 1,2,3,4,6 | AN13: 55
A14: M | B14: 13 | C14: X | D14: X | E14: X | F14: X | G14: X | H14: X | I14: X | J14: X | K14: X | L14: X | M14: X | N14: X | P14: X | Q14: X | R14: X | S14: X | T14: X | U14: X | V14: X | W14: X | X14: X | Y14: X | Z14: X | AA14: X | AB14: X | AC14: X | AD14: X | AE14: X | AF14: X | AG14: X | AH14: X | AI14: X | AJ14: X | AK14: X | AL14: X | AM14: 1,3,6 | AN14: 50
A15: N | B15: 14 | C15: X | D15: X | E15: X | F15: X | G15: X | H15: X | I15: X | J15: X | K15: X | L15: X | M15: X | N15: X | O15: X | Q15: X | R15: X | S15: X | T15: X | U15: X | V15: X | W15: X | X15: X | Y15: X | Z15: X | AA15: X | AB15: X | AC15: X | AD15: X | AE15: X | AF15: X | AG15: X | AH15: X | AI15: X | AJ15: X | AK15: X | AL15: X | AM15: 1,2,3,6 | AN15: 51
A16: O | B16: 15 | C16: X | D16: X | E16: X | F16: X | G16: X | H16: X | I16: X | J16: X | K16: X | L16: X | M16: X | N16: X | O16: X | P16: X | R16: X | S16: X | T16: X | U16: X | V16: X | W16: X | X16: X | Y16: X | Z16: X | AA16: X | AB16: X | AC16: X | AD16: X | AE16: X | AF16: X | AG16: X | AH16: X | AI16: X | AJ16: X | AK16: X | AL16: X | AM16: 1,6 | AN16: 56
A17: P | B17: 16 | C17: X | D17: X | E17: X | F17: X | G17: X | H17: X | I17: X | J17: X | K17: X | L17: X | M17: X | N17: X | O17: X | P17: X | Q17: X | S17: X | T17: X | U17: X | V17: X | W17: X | X17: X | Y17: X | Z17: X | AA17: X | AB17: X | AC17: X | AD17: X | AE17: X | AF17: X | AG17: X | AH17: X | AI17: X | AJ17: X | AK17: X | AL17: X | AM17: 1,2,3,4,5,6 | AN17: X
A18: Q | B18: 17 | C18: X | D18: X | E18: X | F18: X | G18: X | H18: X | I18: X | J18: X | K18: X | L18: X | M18: X | N18: X | O18: X | P18: X | Q18: X | R18: X | T18: X | U18: X | V18: X | W18: X | X18: X | Y18: X | Z18: X | AA18: X | AB18: X | AC18: X | AD18: X | AE18: X | AF18: X | AG18: X | AH18: X | AI18: X | AJ18: X | AK18: X | AL18: X | AM18: 1,3,4,5,6 | AN18: 62
A19: R | B19: 18 | C19: X | D19: X | E19: X | F19: X | G19: X | H19: X | I19: X | J19: X | K19: X | L19: X | M19: X | N19: X | O19: X | P19: X | Q19: X | R19: X | S19: X | U19: X | V19: X | W19: X | X19: X | Y19: X | Z19: X | AA19: X | AB19: X | AC19: X | AD19: X | AE19: X | AF19: X | AG19: X | AH19: X | AI19: X | AJ19: X | AK19: X | AL19: X | AM19: 1,2,3,4,5,6 | AN19: X
A20: S | B20: 19 | C20: X | D20: X | E20: X | F20: X | G20: X | H20: X | I20: X | J20: X | K20: X | L20: X | M20: X | N20: X | O20: X | P20: X | Q20: X | R20: X | S20: X | T20: X | V20: X | W20: X | X20: X | Y20: X | Z20: X | AA20: X | AB20: X | AC20: X | AD20: X | AE20: X | AF20: X | AG20: X | AH20: X | AI20: X | AJ20: X | AK20: X | AL20: X | AM20: 1,4,5 | AN20: 44
A21: T | B21: 20 | C21: X | D21: X | E21: X | F21: X | G21: X | H21: X | I21: X | J21: X | K21: X | L21: X | M21: X | N21: X | O21: X | P21: X | Q21: X | R21: X | S21: X | T21: X | U21: X | W21: X | X21: X | Y21: X | Z21: X | AA21: X | AB21: X | AC21: X | AD21: X | AE21: X | AF21: X | AG21: X | AH21: X | AI21: X | AJ21: X | AK21: X | AL21: X | AM21: 1,2,3,4,5 | AN21: 47
A22: U | B22: 21 | C22: X | D22: X | E22: X | F22: X | G22: X | H22: X | I22: X | J22: X | K22: X | L22: X | M22: X | N22: X | O22: X | P22: X | Q22: X | R22: X | S22: X | T22: X | U22: X | V22: X | X22: X | Y22: X | Z22: X | AA22: X | AB22: X | AC22: X | AD22: X | AE22: X | AF22: X | AG22: X | AH22: X | AI22: X | AJ22: X | AK22: X | AL22: X | AM22: 1,3,5 | AN22: 42
A23: V | B23: 22 | C23: X | D23: X | E23: X | F23: X | G23: X | H23: X | I23: X | J23: X | K23: X | L23: X | M23: X | N23: X | O23: X | P23: X | Q23: X | R23: X | S23: X | T23: X | U23: X | V23: X | W23: X | Y23: X | Z23: X | AA23: X | AB23: X | AC23: X | AD23: X | AE23: X | AF23: X | AG23: X | AH23: X | AI23: X | AJ23: X | AK23: X | AL23: X | AM23: 1,2,5 | AN23: 41
A24: W | B24: 23 | C24: X | D24: X | E24: X | F24: X | G24: X | H24: X | I24: X | J24: X | K24: X | L24: X | M24: X | N24: X | O24: X | P24: X | Q24: X | R24: X | S24: X | T24: X | U24: X | V24: X | W24: X | X24: X | Z24: X | AA24: X | AB24: X | AC24: X | AD24: X | AE24: X | AF24: X | AG24: X | AH24: X | AI24: X | AJ24: X | AK24: X | AL24: X | AM24: 1,5
A25: X | B25: 24 | C25: X | D25: X | E25: X | F25: X | G25: X | H25: X | I25: X | J25: X | K25: X | L25: X | M25: X | N25: X | O25: X | P25: X | Q25: X | R25: X | S25: X | T25: X | U25: X | V25: X | W25: X | X25: X | Y25: X | AA25: X | AB25: X | AC25: X | AD25: X | AE25: X | AF25: X | AG25: X | AH25: X | AI25: X | AJ25: X | AK25: X | AL25: X | AM25: 1,2,3,4,5 | AN25: 47
A26: Y | B26: 25 | C26: X | D26: X | E26: X | F26: X | G26: X | H26: X | I26: X | J26: X | K26: X | L26: X | M26: X | N26: X | O26: X | P26: X | Q26: X | R26: X | S26: X | T26: X | U26: X | V26: X | W26: X | X26: X | Y26: X | Z26: X | AB26: X | AC26: X | AD26: X | AE26: X | AF26: X | AG26: X | AH26: X | AI26: X | AJ26: X | AK26: X | AL26: X | AM26: 1,3,4 | AN26: 38
A27: Z | B27: 26 | C27: X | D27: X | E27: X | F27: X | G27: X | H27: X | I27: X | J27: X | K27: X | L27: X | M27: X | N27: X | O27: X | P27: X | Q27: X | R27: X | S27: X | T27: X | U27: X | V27: X | W27: X | X27: X | Y27: X | Z27: X | AA27: X | AC27: X | AD27: X | AE27: X | AF27: X | AG27: X | AH27: X | AI27: X | AJ27: X | AK27: X | AL27: X | AM27: 1,2,4 | AN27: 37
A28: 0 | B28: 27 | C28: X | D28: X | E28: X | F28: X | G28: X | H28: X | I28: X | J28: X | K28: X | L28: X | M28: X | N28: X | O28: X | P28: X | Q28: X | R28: X | S28: X | T28: X | U28: X | V28: X | W28: X | X28: X | Y28: X | Z28: X | AA28: X | AB28: X | AD28: X | AE28: X | AF28: X | AG28: X | AH28: X | AI28: X | AJ28: X | AK28: X | AL28: X | AM28: 1,4
A29: 1 | B29: 28 | C29: X | D29: X | E29: X | F29: X | G29: X | H29: X | I29: X | J29: X | K29: X | L29: X | M29: X | N29: X | O29: X | P29: X | Q29: X | R29: X | S29: X | T29: X | U29: X | V29: X | W29: X | X29: X | Y29: X | Z29: X | AA29: X | AB29: X | AC29: X | AE29: X | AF29: X | AG29: X | AH29: X | AI29: X | AJ29: X | AK29: X | AL29: X | AM29: 1,2,3,4 | AN29: 39
A30: 2 | B30: 29 | C30: X | D30: X | E30: X | F30: X | G30: X | H30: X | I30: X | J30: X | K30: X | L30: X | M30: X | N30: X | O30: X | P30: X | Q30: X | R30: X | S30: X | T30: X | U30: X | V30: X | W30: X | X30: X | Y30: X | Z30: X | AA30: X | AB30: X | AC30: X | AD30: X | AF30: X | AG30: X | AH30: X | AI30: X | AJ30: X | AK30: X | AL30: X | AM30: 1,3
A31: 3 | B31: 30 | C31: X | D31: X | E31: X | F31: X | G31: X | H31: X | I31: X | J31: X | K31: X | L31: X | M31: X | N31: X | O31: X | P31: X | Q31: X | R31: X | S31: X | T31: X | U31: X | V31: X | W31: X | X31: X | Y31: X | Z31: X | AA31: X | AB31: X | AC31: X | AD31: X | AE31: X | AG31: X | AH31: X | AI31: X | AJ31: X | AK31: X | AL31: X | AM31: 1,2 | AN31: 49
A32: 4 | B32: 31 | C32: X | D32: X | E32: X | F32: X | G32: X | H32: X | I32: X | J32: X | K32: X | L32: X | M32: X | N32: X | O32: X | P32: X | Q32: X | R32: X | S32: X | T32: X | U32: X | V32: X | W32: X | X32: X | Y32: X | Z32: X | AA32: X | AB32: X | AC32: X | AD32: X | AE32: X | AF32: X | AH32: X | AI32: X | AJ32: X | AK32: X | AL32: X | AM32: 1 | AN32: 40,48
A33: 5 | B33: 32 | C33: X | D33: X | E33: X | F33: X | G33: X | H33: X | I33: X | J33: X | K33: X | L33: X | M33: X | N33: X | O33: X | P33: X | Q33: X | R33: X | S33: X | T33: X | U33: X | V33: X | W33: X | X33: X | Y33: X | Z33: X | AA33: X | AB33: X | AC33: X | AD33: X | AE33: X | AF33: X | AG33: X | AI33: X | AJ33: X | AK33: X | AL33: X | AM33: 1,2,3,4,5,6 | AN33: X
A34: 6 | B34: 33 | C34: X | D34: X | E34: X | F34: X | G34: X | H34: X | I34: X | J34: X | K34: X | L34: X | M34: X | N34: X | O34: X | P34: X | Q34: X | R34: X | S34: X | T34: X | U34: X | V34: X | W34: X | X34: X | Y34: X | Z34: X | AA34: X | AB34: X | AC34: X | AD34: X | AE34: X | AF34: X | AG34: X | AH34: X | AJ34: X | AK34: X | AL34: X | AM34: 1,3,4,5,6 | AN34: 62
A35: 7 | B35: 34 | C35: X | D35: X | E35: X | F35: X | G35: X | H35: X | I35: X | J35: X | K35: X | L35: X | M35: X | N35: X | O35: X | P35: X | Q35: X | R35: X | S35: X | T35: X | U35: X | V35: X | W35: X | X35: X | Y35: X | Z35: X | AA35: X | AB35: X | AC35: X | AD35: X | AE35: X | AF35: X | AG35: X | AH35: X | AI35: X | AK35: X | AL35: X | AM35: 1,2,4,5,6 | AN35: 61
A36: 8 | B36: 35 | C36: X | D36: X | E36: X | F36: X | G36: X | H36: X | I36: X | J36: X | K36: X | L36: X | M36: X | N36: X | O36: X | P36: X | Q36: X | R36: X | S36: X | T36: X | U36: X | V36: X | W36: X | X36: X | Y36: X | Z36: X | AA36: X | AB36: X | AC36: X | AD36: X | AE36: X | AF36: X | AG36: X | AH36: X | AI36: X | AJ36: X | AL36: X | AM36: 1,4,5,6 | AN36: 60
A37: 9 | B37: 36 | C37: X | D37: X | E37: X | F37: X | G37: X | H37: X | I37: X | J37: X | K37: X | L37: X | M37: X | N37: X | O37: X | P37: X | Q37: X | R37: X | S37: X | T37: X | U37: X | V37: X | W37: X | X37: X | Y37: X | Z37: X | AA37: X | AB37: X | AC37: X | AD37: X | AE37: X | AF37: X | AG37: X | AH37: X | AI37: X | AJ37: X | AK37: X | AM37: 1,2,3,4,5,6 | AN37: X
A38: Z | B38: 37 | C38: X | D38: X | E38: X | F38: X | G38: X | H38: X | I38: X | J38: X | K38: X | L38: X | M38: X | N38: X | O38: X | P38: X | Q38: X | R38: X | S38: X | T38: X | U38: X | V38: X | W38: X | X38: X | Y38: X | Z38: X | AA38: X | AC38: 37 | AD38: X | AE38: X | AF38: 37 | AG38: 37 | AH38: X | AI38: X | AJ38: X | AK38: X | AL38: X | AM38: 3,5,6 | AN38: Z | AP38: Index | AQ38: A | AR38: B | AS38: C | AT38: D | AU38: E | AV38: F | AW38: G | AX38: H | AY38: I | AZ38: J | BA38: K | BB38: L | BC38: M | BD38: N | BE38: O | BF38: P | BG38: Q | BH38: R | BI38: S | BJ38: T | BK38: U | BL38: V | BM38: W | BN38: X | BO38: Y | BP38: Z | BQ38: 0 | BR38: 1 | BS38: 2 | BT38: 3 | BU38: 4 | BV38: 5 | BW38: 6 | BX38: 7 | BY38: 8 | BZ38: 9
A39: Y | B39: 38 | C39: X | D39: X | E39: X | F39: X | G39: X | H39: X | I39: X | J39: X | K39: X | L39: X | M39: X | N39: X | O39: X | P39: X | Q39: X | R39: X | S39: X | T39: X | U39: 38 | V39: X | W39: 38 | X39: X | Y39: 38 | Z39: X | AB39: X | AC39: 38 | AD39: X | AE39: 38 | AF39: X | AG39: 38 | AH39: X | AI39: X | AJ39: X | AK39: X | AL39: X | AM39: 2,5,6 | AN39: Y | AP39: 1 | AQ39: X | AR39: X | AS39: X | AT39: X | AU39: X | AV39: X | AW39: X | AX39: X | AY39: X | AZ39: X | BA39: X | BB39: X | BC39: X | BD39: X | BE39: X | BF39: X | BG39: X | BH39: X | BI39: X | BJ39: X | BK39: X | BL39: X | BM39: X | BN39: X | BO39: X | BP39: X | BQ39: X | BR39: X | BS39: X | BT39: X | BU39: X | BV39: X | BW39: X | BX39: X | BY39: X | BZ39: X
A40: 1 | B40: 39 | C40: X | D40: X | E40: X | F40: X | G40: X | H40: X | I40: X | J40: X | K40: X | L40: X | M40: X | N40: X | O40: X | P40: X | Q40: X | R40: X | S40: X | T40: X | U40: X | V40: X | W40: X | X40: X | Y40: X | Z40: X | AA40: 38 | AB40: 37 | AC40: 39 | AE40: 39 | AF40: 39 | AG40: 39 | AH40: X | AI40: X | AJ40: X | AK40: X | AL40: X | AM40: 5,6 | AN40: 1 | AP40: 2 | AQ40: X | AR40: X | AS40: X | AT40: X | AU40: X | AV40: X | AW40: X | AX40: X | AY40: X | AZ40: X | BB40: X | BD40: X | BF40: X | BH40: X | BJ40: X | BL40: X | BN40: X | BP40: X | BR40: X | BT40: X | BV40: X | BX40: X | BZ40: X
...
